{
 "cells": [
  {
   "cell_type": "markdown",
   "metadata": {},
   "source": [
    "# Pydantic を使ったDictのバリデーション\n",
    "\n",
    "今まで、補完を効かせるためにTypedDictを使ってきたが、Pydanticに食わせればよい"
   ]
  },
  {
   "cell_type": "code",
   "execution_count": 34,
   "metadata": {},
   "outputs": [],
   "source": [
    "import dataclasses\n",
    "from typing import cast\n",
    "\n",
    "from datetime import datetime\n",
    "import pydantic"
   ]
  },
  {
   "cell_type": "code",
   "execution_count": 35,
   "metadata": {},
   "outputs": [],
   "source": [
    "class User(pydantic.BaseModel):\n",
    "    id: int\n",
    "    name: str\n",
    "    signup_ts: datetime\n",
    "\n",
    "@dataclasses.dataclass\n",
    "class NUser:\n",
    "    id: int\n",
    "    name: str\n",
    "    signup_ts: datetime\n"
   ]
  },
  {
   "cell_type": "code",
   "execution_count": 36,
   "metadata": {},
   "outputs": [],
   "source": [
    "u1 = User(id=1, name='John Doe', signup_ts=datetime.fromisoformat('2017-06-01T12:22:00'))\n",
    "u2 = NUser(id=1, name='John Doe', signup_ts=datetime.fromisoformat('2017-06-01T12:22:00'))"
   ]
  },
  {
   "cell_type": "code",
   "execution_count": 37,
   "metadata": {},
   "outputs": [
    {
     "ename": "ValueError",
     "evalue": "\"User\" object has no field \"test\"",
     "output_type": "error",
     "traceback": [
      "\u001b[0;31m---------------------------------------------------------------------------\u001b[0m",
      "\u001b[0;31mValueError\u001b[0m                                Traceback (most recent call last)",
      "Cell \u001b[0;32mIn[37], line 1\u001b[0m\n\u001b[0;32m----> 1\u001b[0m \u001b[43mu1\u001b[49m\u001b[38;5;241;43m.\u001b[39;49m\u001b[43mtest\u001b[49m \u001b[38;5;241m=\u001b[39m \u001b[38;5;124m\"\u001b[39m\u001b[38;5;124m\"\u001b[39m\n",
      "File \u001b[0;32m~/ghq/github.com/74th/python-testing/nb3.11/.venv/lib/python3.12/site-packages/pydantic/main.py:820\u001b[0m, in \u001b[0;36mBaseModel.__setattr__\u001b[0;34m(self, name, value)\u001b[0m\n\u001b[1;32m    817\u001b[0m     \u001b[38;5;28mself\u001b[39m\u001b[38;5;241m.\u001b[39m__pydantic_validator__\u001b[38;5;241m.\u001b[39mvalidate_assignment(\u001b[38;5;28mself\u001b[39m, name, value)\n\u001b[1;32m    818\u001b[0m \u001b[38;5;28;01melif\u001b[39;00m \u001b[38;5;28mself\u001b[39m\u001b[38;5;241m.\u001b[39mmodel_config\u001b[38;5;241m.\u001b[39mget(\u001b[38;5;124m'\u001b[39m\u001b[38;5;124mextra\u001b[39m\u001b[38;5;124m'\u001b[39m) \u001b[38;5;241m!=\u001b[39m \u001b[38;5;124m'\u001b[39m\u001b[38;5;124mallow\u001b[39m\u001b[38;5;124m'\u001b[39m \u001b[38;5;129;01mand\u001b[39;00m name \u001b[38;5;129;01mnot\u001b[39;00m \u001b[38;5;129;01min\u001b[39;00m \u001b[38;5;28mself\u001b[39m\u001b[38;5;241m.\u001b[39mmodel_fields:\n\u001b[1;32m    819\u001b[0m     \u001b[38;5;66;03m# TODO - matching error\u001b[39;00m\n\u001b[0;32m--> 820\u001b[0m     \u001b[38;5;28;01mraise\u001b[39;00m \u001b[38;5;167;01mValueError\u001b[39;00m(\u001b[38;5;124mf\u001b[39m\u001b[38;5;124m'\u001b[39m\u001b[38;5;124m\"\u001b[39m\u001b[38;5;132;01m{\u001b[39;00m\u001b[38;5;28mself\u001b[39m\u001b[38;5;241m.\u001b[39m\u001b[38;5;18m__class__\u001b[39m\u001b[38;5;241m.\u001b[39m\u001b[38;5;18m__name__\u001b[39m\u001b[38;5;132;01m}\u001b[39;00m\u001b[38;5;124m\"\u001b[39m\u001b[38;5;124m object has no field \u001b[39m\u001b[38;5;124m\"\u001b[39m\u001b[38;5;132;01m{\u001b[39;00mname\u001b[38;5;132;01m}\u001b[39;00m\u001b[38;5;124m\"\u001b[39m\u001b[38;5;124m'\u001b[39m)\n\u001b[1;32m    821\u001b[0m \u001b[38;5;28;01melif\u001b[39;00m \u001b[38;5;28mself\u001b[39m\u001b[38;5;241m.\u001b[39mmodel_config\u001b[38;5;241m.\u001b[39mget(\u001b[38;5;124m'\u001b[39m\u001b[38;5;124mextra\u001b[39m\u001b[38;5;124m'\u001b[39m) \u001b[38;5;241m==\u001b[39m \u001b[38;5;124m'\u001b[39m\u001b[38;5;124mallow\u001b[39m\u001b[38;5;124m'\u001b[39m \u001b[38;5;129;01mand\u001b[39;00m name \u001b[38;5;129;01mnot\u001b[39;00m \u001b[38;5;129;01min\u001b[39;00m \u001b[38;5;28mself\u001b[39m\u001b[38;5;241m.\u001b[39mmodel_fields:\n\u001b[1;32m    822\u001b[0m     \u001b[38;5;28;01mif\u001b[39;00m \u001b[38;5;28mself\u001b[39m\u001b[38;5;241m.\u001b[39mmodel_extra \u001b[38;5;129;01mand\u001b[39;00m name \u001b[38;5;129;01min\u001b[39;00m \u001b[38;5;28mself\u001b[39m\u001b[38;5;241m.\u001b[39mmodel_extra:\n",
      "\u001b[0;31mValueError\u001b[0m: \"User\" object has no field \"test\""
     ]
    }
   ],
   "source": [
    "u1.test = \"\""
   ]
  },
  {
   "cell_type": "code",
   "execution_count": 38,
   "metadata": {},
   "outputs": [],
   "source": [
    "u2.test = \"\""
   ]
  },
  {
   "cell_type": "markdown",
   "metadata": {},
   "source": [
    "Pydanticのモデルを使うと、パラメータ増やしたりできなくなる"
   ]
  },
  {
   "cell_type": "code",
   "execution_count": 39,
   "metadata": {},
   "outputs": [],
   "source": [
    "un = NUser(id=1, name='John Doe', signup_ts=100)\n",
    "u = User(id=1, name='John Doe', signup_ts=100)"
   ]
  },
  {
   "cell_type": "markdown",
   "metadata": {},
   "source": [
    "実行はできて、動的には検証してくれてない？？？"
   ]
  },
  {
   "cell_type": "code",
   "execution_count": 31,
   "metadata": {},
   "outputs": [
    {
     "name": "stdout",
     "output_type": "stream",
     "text": [
      "NUser(id=100, name=200, signup_ts=datetime.datetime(2024, 4, 30, 12, 22))\n"
     ]
    },
    {
     "ename": "ValidationError",
     "evalue": "1 validation error for User\nname\n  Input should be a valid string [type=string_type, input_value=200, input_type=int]\n    For further information visit https://errors.pydantic.dev/2.7/v/string_type",
     "output_type": "error",
     "traceback": [
      "\u001b[0;31m---------------------------------------------------------------------------\u001b[0m",
      "\u001b[0;31mValidationError\u001b[0m                           Traceback (most recent call last)",
      "Cell \u001b[0;32mIn[31], line 8\u001b[0m\n\u001b[1;32m      6\u001b[0m un \u001b[38;5;241m=\u001b[39m NUser(\u001b[38;5;241m*\u001b[39m\u001b[38;5;241m*\u001b[39mv)\n\u001b[1;32m      7\u001b[0m \u001b[38;5;28mprint\u001b[39m(un)\n\u001b[0;32m----> 8\u001b[0m u \u001b[38;5;241m=\u001b[39m \u001b[43mUser\u001b[49m\u001b[43m(\u001b[49m\u001b[38;5;241;43m*\u001b[39;49m\u001b[38;5;241;43m*\u001b[39;49m\u001b[43mv\u001b[49m\u001b[43m)\u001b[49m\n\u001b[1;32m      9\u001b[0m \u001b[38;5;28mprint\u001b[39m(u)\n",
      "File \u001b[0;32m~/ghq/github.com/74th/python-testing/nb3.11/.venv/lib/python3.12/site-packages/pydantic/main.py:175\u001b[0m, in \u001b[0;36mBaseModel.__init__\u001b[0;34m(self, **data)\u001b[0m\n\u001b[1;32m    173\u001b[0m \u001b[38;5;66;03m# `__tracebackhide__` tells pytest and some other tools to omit this function from tracebacks\u001b[39;00m\n\u001b[1;32m    174\u001b[0m __tracebackhide__ \u001b[38;5;241m=\u001b[39m \u001b[38;5;28;01mTrue\u001b[39;00m\n\u001b[0;32m--> 175\u001b[0m \u001b[38;5;28;43mself\u001b[39;49m\u001b[38;5;241;43m.\u001b[39;49m\u001b[43m__pydantic_validator__\u001b[49m\u001b[38;5;241;43m.\u001b[39;49m\u001b[43mvalidate_python\u001b[49m\u001b[43m(\u001b[49m\u001b[43mdata\u001b[49m\u001b[43m,\u001b[49m\u001b[43m \u001b[49m\u001b[43mself_instance\u001b[49m\u001b[38;5;241;43m=\u001b[39;49m\u001b[38;5;28;43mself\u001b[39;49m\u001b[43m)\u001b[49m\n",
      "\u001b[0;31mValidationError\u001b[0m: 1 validation error for User\nname\n  Input should be a valid string [type=string_type, input_value=200, input_type=int]\n    For further information visit https://errors.pydantic.dev/2.7/v/string_type"
     ]
    }
   ],
   "source": [
    "v = {\n",
    "    \"id\": 100,\n",
    "    \"name\": 200,\n",
    "    \"signup_ts\": datetime.fromisoformat(\"2024-04-30T12:22:00\"),\n",
    "}\n",
    "un = NUser(**v)\n",
    "print(un)\n",
    "u = User(**v)\n",
    "print(u)"
   ]
  },
  {
   "cell_type": "markdown",
   "metadata": {},
   "source": [
    "エラーになってくれる"
   ]
  },
  {
   "cell_type": "code",
   "execution_count": 32,
   "metadata": {},
   "outputs": [
    {
     "name": "stdout",
     "output_type": "stream",
     "text": [
      "id=100 name='200' signup_ts=datetime.datetime(2024, 4, 30, 12, 22)\n"
     ]
    }
   ],
   "source": [
    "v = {\n",
    "    \"id\": 100,\n",
    "    \"name\": \"200\",\n",
    "    \"signup_ts\": \"2024-04-30T12:22:00\",\n",
    "}\n",
    "u = User(**v)\n",
    "print(u)"
   ]
  },
  {
   "cell_type": "markdown",
   "metadata": {},
   "source": [
    "変換できるなら、良い感じに変換しておいてくれる"
   ]
  },
  {
   "cell_type": "code",
   "execution_count": 40,
   "metadata": {},
   "outputs": [],
   "source": [
    "@pydantic.dataclasses.dataclass\n",
    "class DUser:\n",
    "    id: int\n",
    "    name: str\n",
    "    signup_ts: datetime"
   ]
  },
  {
   "cell_type": "code",
   "execution_count": 42,
   "metadata": {},
   "outputs": [
    {
     "name": "stdout",
     "output_type": "stream",
     "text": [
      "DUser(id=100, name='200', signup_ts=datetime.datetime(2024, 4, 30, 12, 22))\n"
     ]
    }
   ],
   "source": [
    "v = {\n",
    "    \"id\": 100,\n",
    "    \"name\": \"200\",\n",
    "    \"signup_ts\": \"2024-04-30T12:22:00\",\n",
    "}\n",
    "u = DUser(**v)\n",
    "print(u)"
   ]
  },
  {
   "cell_type": "markdown",
   "metadata": {},
   "source": [
    "## 構造的なやつ"
   ]
  },
  {
   "cell_type": "code",
   "execution_count": 43,
   "metadata": {},
   "outputs": [],
   "source": [
    "\n",
    "@pydantic.dataclasses.dataclass\n",
    "class Pos:\n",
    "    lat: pydantic.types.StrictFloat\n",
    "    lon: pydantic.types.StrictFloat\n",
    "\n",
    "@pydantic.dataclasses.dataclass\n",
    "class Response:\n",
    "    route: list[Pos]"
   ]
  },
  {
   "cell_type": "code",
   "execution_count": 45,
   "metadata": {},
   "outputs": [
    {
     "data": {
      "text/plain": [
       "Response(route=[Pos(lat=1.0, lon=2.0), Pos(lat=3.0, lon=4.0)])"
      ]
     },
     "execution_count": 45,
     "metadata": {},
     "output_type": "execute_result"
    }
   ],
   "source": [
    "p1=Pos(lat=1.0, lon=2.0)\n",
    "p2=Pos(lat=3.0, lon=4.0)\n",
    "\n",
    "Response(route=[p1, p2])"
   ]
  },
  {
   "cell_type": "code",
   "execution_count": 46,
   "metadata": {},
   "outputs": [
    {
     "ename": "ValidationError",
     "evalue": "1 validation error for Response\nroute.0\n  Input should be a dictionary or an instance of Pos [type=dataclass_type, input_value=[(1, 2), (3, 4)], input_type=list]\n    For further information visit https://errors.pydantic.dev/2.7/v/dataclass_type",
     "output_type": "error",
     "traceback": [
      "\u001b[0;31m---------------------------------------------------------------------------\u001b[0m",
      "\u001b[0;31mValidationError\u001b[0m                           Traceback (most recent call last)",
      "Cell \u001b[0;32mIn[46], line 1\u001b[0m\n\u001b[0;32m----> 1\u001b[0m \u001b[43mResponse\u001b[49m\u001b[43m(\u001b[49m\u001b[43mroute\u001b[49m\u001b[38;5;241;43m=\u001b[39;49m\u001b[43m[\u001b[49m\u001b[43m[\u001b[49m\u001b[43m(\u001b[49m\u001b[38;5;241;43m1\u001b[39;49m\u001b[43m,\u001b[49m\u001b[38;5;241;43m2\u001b[39;49m\u001b[43m)\u001b[49m\u001b[43m,\u001b[49m\u001b[43m(\u001b[49m\u001b[38;5;241;43m3\u001b[39;49m\u001b[43m,\u001b[49m\u001b[38;5;241;43m4\u001b[39;49m\u001b[43m)\u001b[49m\u001b[43m]\u001b[49m\u001b[43m]\u001b[49m\u001b[43m)\u001b[49m\n",
      "File \u001b[0;32m~/ghq/github.com/74th/python-testing/nb3.11/.venv/lib/python3.12/site-packages/pydantic/_internal/_dataclasses.py:140\u001b[0m, in \u001b[0;36mcomplete_dataclass.<locals>.__init__\u001b[0;34m(__dataclass_self__, *args, **kwargs)\u001b[0m\n\u001b[1;32m    138\u001b[0m __tracebackhide__ \u001b[38;5;241m=\u001b[39m \u001b[38;5;28;01mTrue\u001b[39;00m\n\u001b[1;32m    139\u001b[0m s \u001b[38;5;241m=\u001b[39m __dataclass_self__\n\u001b[0;32m--> 140\u001b[0m \u001b[43ms\u001b[49m\u001b[38;5;241;43m.\u001b[39;49m\u001b[43m__pydantic_validator__\u001b[49m\u001b[38;5;241;43m.\u001b[39;49m\u001b[43mvalidate_python\u001b[49m\u001b[43m(\u001b[49m\u001b[43mArgsKwargs\u001b[49m\u001b[43m(\u001b[49m\u001b[43margs\u001b[49m\u001b[43m,\u001b[49m\u001b[43m \u001b[49m\u001b[43mkwargs\u001b[49m\u001b[43m)\u001b[49m\u001b[43m,\u001b[49m\u001b[43m \u001b[49m\u001b[43mself_instance\u001b[49m\u001b[38;5;241;43m=\u001b[39;49m\u001b[43ms\u001b[49m\u001b[43m)\u001b[49m\n",
      "\u001b[0;31mValidationError\u001b[0m: 1 validation error for Response\nroute.0\n  Input should be a dictionary or an instance of Pos [type=dataclass_type, input_value=[(1, 2), (3, 4)], input_type=list]\n    For further information visit https://errors.pydantic.dev/2.7/v/dataclass_type"
     ]
    }
   ],
   "source": [
    "Response(route=[[(1,2),(3,4)]])"
   ]
  },
  {
   "cell_type": "code",
   "execution_count": 51,
   "metadata": {},
   "outputs": [],
   "source": [
    "@pydantic.dataclasses.dataclass\n",
    "class Response2:\n",
    "    route: list[tuple[float, float]]\n",
    "\n",
    "@dataclasses.dataclass\n",
    "class NResponse2:\n",
    "    route: list[tuple[float, float]]"
   ]
  },
  {
   "cell_type": "code",
   "execution_count": 48,
   "metadata": {},
   "outputs": [
    {
     "data": {
      "text/plain": [
       "Response2(route=[(1.1, 2.2), (3.3, 4.4)])"
      ]
     },
     "execution_count": 48,
     "metadata": {},
     "output_type": "execute_result"
    }
   ],
   "source": [
    "Response2(route=[(1.1,2.2),(3.3,4.4)])"
   ]
  },
  {
   "cell_type": "code",
   "execution_count": 49,
   "metadata": {},
   "outputs": [
    {
     "ename": "ValidationError",
     "evalue": "1 validation error for Response2\nroute.0\n  Tuple should have at most 2 items after validation, not 3 [type=too_long, input_value=(1.1, 2.2, 3.3), input_type=tuple]\n    For further information visit https://errors.pydantic.dev/2.7/v/too_long",
     "output_type": "error",
     "traceback": [
      "\u001b[0;31m---------------------------------------------------------------------------\u001b[0m",
      "\u001b[0;31mValidationError\u001b[0m                           Traceback (most recent call last)",
      "Cell \u001b[0;32mIn[49], line 1\u001b[0m\n\u001b[0;32m----> 1\u001b[0m \u001b[43mResponse2\u001b[49m\u001b[43m(\u001b[49m\u001b[43mroute\u001b[49m\u001b[38;5;241;43m=\u001b[39;49m\u001b[43m[\u001b[49m\u001b[43m(\u001b[49m\u001b[38;5;241;43m1.1\u001b[39;49m\u001b[43m,\u001b[49m\u001b[38;5;241;43m2.2\u001b[39;49m\u001b[43m,\u001b[49m\u001b[38;5;241;43m3.3\u001b[39;49m\u001b[43m)\u001b[49m\u001b[43m,\u001b[49m\u001b[43m(\u001b[49m\u001b[38;5;241;43m3.3\u001b[39;49m\u001b[43m,\u001b[49m\u001b[38;5;241;43m4.4\u001b[39;49m\u001b[43m)\u001b[49m\u001b[43m]\u001b[49m\u001b[43m)\u001b[49m\n",
      "File \u001b[0;32m~/ghq/github.com/74th/python-testing/nb3.11/.venv/lib/python3.12/site-packages/pydantic/_internal/_dataclasses.py:140\u001b[0m, in \u001b[0;36mcomplete_dataclass.<locals>.__init__\u001b[0;34m(__dataclass_self__, *args, **kwargs)\u001b[0m\n\u001b[1;32m    138\u001b[0m __tracebackhide__ \u001b[38;5;241m=\u001b[39m \u001b[38;5;28;01mTrue\u001b[39;00m\n\u001b[1;32m    139\u001b[0m s \u001b[38;5;241m=\u001b[39m __dataclass_self__\n\u001b[0;32m--> 140\u001b[0m \u001b[43ms\u001b[49m\u001b[38;5;241;43m.\u001b[39;49m\u001b[43m__pydantic_validator__\u001b[49m\u001b[38;5;241;43m.\u001b[39;49m\u001b[43mvalidate_python\u001b[49m\u001b[43m(\u001b[49m\u001b[43mArgsKwargs\u001b[49m\u001b[43m(\u001b[49m\u001b[43margs\u001b[49m\u001b[43m,\u001b[49m\u001b[43m \u001b[49m\u001b[43mkwargs\u001b[49m\u001b[43m)\u001b[49m\u001b[43m,\u001b[49m\u001b[43m \u001b[49m\u001b[43mself_instance\u001b[49m\u001b[38;5;241;43m=\u001b[39;49m\u001b[43ms\u001b[49m\u001b[43m)\u001b[49m\n",
      "\u001b[0;31mValidationError\u001b[0m: 1 validation error for Response2\nroute.0\n  Tuple should have at most 2 items after validation, not 3 [type=too_long, input_value=(1.1, 2.2, 3.3), input_type=tuple]\n    For further information visit https://errors.pydantic.dev/2.7/v/too_long"
     ]
    }
   ],
   "source": [
    "Response2(route=[(1.1,2.2,3.3),(3.3,4.4)])"
   ]
  },
  {
   "cell_type": "code",
   "execution_count": 52,
   "metadata": {},
   "outputs": [
    {
     "data": {
      "text/plain": [
       "NResponse2(route=[(1.1, 2.2, 3.3), (3.3, 4.4)])"
      ]
     },
     "execution_count": 52,
     "metadata": {},
     "output_type": "execute_result"
    }
   ],
   "source": [
    "NResponse2(route=[(1.1,2.2,3.3),(3.3,4.4)])"
   ]
  },
  {
   "cell_type": "markdown",
   "metadata": {},
   "source": [
    "従来のdataclassなら通ってしまう"
   ]
  },
  {
   "cell_type": "code",
   "execution_count": null,
   "metadata": {},
   "outputs": [],
   "source": []
  }
 ],
 "metadata": {
  "kernelspec": {
   "display_name": ".venv",
   "language": "python",
   "name": "python3"
  },
  "language_info": {
   "codemirror_mode": {
    "name": "ipython",
    "version": 3
   },
   "file_extension": ".py",
   "mimetype": "text/x-python",
   "name": "python",
   "nbconvert_exporter": "python",
   "pygments_lexer": "ipython3",
   "version": "3.12.2"
  }
 },
 "nbformat": 4,
 "nbformat_minor": 2
}
